<?xml version="1.0"?>
<robot xmlns:xacro="http://www.ros.org/wiki/xacro" name="robot_name">

    <xacro:include filename="gazebo_plugins.xacro"/>
    <xacro:property name="chassis_length" value="0.45"/>
    <xacro:property name="chassis_width" value="0.4"/>

    <!--                Base Link               -->
        <link name="base_link"/>

        <joint name="base_footprint_joint" type="fixed">
            <parent link="base_link"/>
            <child link="base_footprint"/>
            <origin xyz="0 0 0" rpy="0 0 0"/>
        </joint>

        <link name="base_footprint"/>



        <!--                Chassis Joint               -->
        <joint name="chassis_joint" type="fixed">
            <origin xyz="0.0 0.0 0.0" rpy="0.0 0.0 0.0"/>
            <parent link="base_link"/>
            <child link="chassis_link"/>
            <axis xyz="0.0 0.0 0.0"/>
        </joint>

        <link name="chassis_link">
            <inertial>
                <origin xyz="0.0 0.0 0.0" rpy="0.0 0.0 0.0"/>
                <mass value="2.5"/>
                <inertia ixx="0.04167" ixy="0.0" ixz="0.0" iyy="0.05021" iyz="0.0" izz="0.07552"/>
            </inertial>
            <visual>
                <origin xyz="0.0 0.0 0.0" rpy="0.0 0.0 0.0"/>
                <geometry>
                    <box size="${chassis_length} 0.4 0.2"/>
                </geometry>
                <material name="dark">
                    <color rgba="1.0 1.0 1.0 1.0"/>
                </material>
            </visual>
            <collision>
                <origin xyz="0.0 0.0 0.0" rpy="0.0 0.0 0.0"/>
                <geometry>
                    <box size="0.45 0.4 0.2"/>
                </geometry>
            </collision>
        </link>



        <!--                Left Wheel Joint               -->
        <joint name="wheel_L_joint" type="continuous">
            <origin xyz="0 0.225 -0.03" rpy="-1.57 0.0 0.0"/>
            <parent link="base_link"/>
            <child link="wheel_L_link"/>
            <axis xyz="0 0 1"/>
        </joint>

        <link name="wheel_L_link">
            <inertial>
                <origin xyz="0.0 0.0 0.0" rpy="0.0 0.0 0.0"/>
                <mass value="0.3"/>
                <inertia ixx="0.0015" ixy="0.0" ixz="0.0" iyy="0.0015" iyz="0.0" izz="0.0008125"/>
            </inertial>
            <visual>
                <origin xyz="0.0 0.0 0.0" rpy="0.0 0.0 0.0"/>
                <geometry>
                    <cylinder radius="0.1" length="0.05"/>
                </geometry>
                <material name="goat">
                    <color rgba="0.1 0.7 0.7 1.0"/>
                </material>
            </visual>
            <collision>
                <origin xyz="0.0 0.0 0.0" rpy="0.0 0.0 0.0"/>
                <geometry>
                    <cylinder radius="0.1" length="0.05"/>
                </geometry>
            </collision>
        </link>



        <!--           Right Wheel Joint              -->
        <joint name="wheel_R_joint" type="continuous">
            <origin xyz="0 -0.225 -0.03" rpy="1.57 0.0 0.0"/>
            <parent link="base_link"/>
            <child link="wheel_R_link"/>
            <axis xyz="0 0 -1"/>
        </joint>

        <link name="wheel_R_link">
            <inertial>
                <origin xyz="0.0 0.0 0.0" rpy="0.0 0.0 0.0"/>
                <mass value="0.3"/>
                <inertia ixx="0.0015" ixy="0.0" ixz="0.0" iyy="0.0015" iyz="0.0" izz="0.0008125"/>
            </inertial>
            <visual>
                <origin xyz="0.0 0.0 0.0" rpy="0.0 0.0 0.0"/>
                <geometry>
                    <cylinder radius="0.1" length="0.05"/>
                </geometry>
                <material name="goat">
                    <color rgba="0.1 0.7 0.7 1.0"/>
                </material>
            </visual>
            <collision>
                <origin xyz="0.0 0.0 0.0" rpy="0.0 0.0 0.0"/>
                <geometry>
                    <cylinder radius="0.1" length="0.05"/>
                </geometry>
            </collision>
        </link>

        



        <!--                Caster wheel joints & links              -->
        <joint name="caster_wheelF_joint" type="fixed">
            <parent link="chassis_link"/>
            <child link="caster_wheelF"/>
            <origin xyz="0.15 0 -0.1" rpy="0.0 0 0"/>
        </joint>
        
        <link name="caster_wheelF">
            <inertial>
                <origin xyz="0.0 0.0 0.0" rpy="0.0 0.0 0.0"/>
                <mass value="0.15"/>
                <inertia ixx="0.000054" ixy="0.0" ixz="0.0" iyy="0.000054" iyz="0.0" izz="0.000054"/>
            </inertial>
            <visual>
                <origin xyz="0.0 0.0 0.0" rpy=" 0.0 0.0 0.0"/>
                <geometry>
                    <sphere radius="0.03"/>
                </geometry>
                <material name="black">
                    <color rgba="0.0 0.0 0.0 1.0"/>
                </material>
            </visual>
            <collision>
                <origin xyz="0.0 0.0 0.0" rpy="0.0 0.0 0.0"/>
                <geometry>
                    <sphere radius="0.03"/>
                </geometry>
            </collision>
        </link>

        <gazebo reference="caster_wheelF">
            <material>Gazebo/White</material>
            <mu1 value="0.001"/>
            <mu2 value="0.001"/>
        </gazebo>

        <joint name="caster_wheelB_joint" type="fixed">
            <parent link="chassis_link"/>
            <child link="caster_wheelB"/>
            <origin xyz="-0.15 0 -0.1" rpy="0.0 0 0"/>
        </joint>
        
        <link name="caster_wheelB">
            <inertial>
                <origin xyz="0.0 0.0 0.0" rpy="0.0 0.0 0.0"/>
                <mass value="0.15"/>
                <inertia ixx="0.000054" ixy="0.0" ixz="0.0" iyy="0.000054" iyz="0.0" izz="0.000054"/>
            </inertial>
            <visual>
                <origin xyz="0.0 0.0 0.0" rpy=" 0.0 0.0 0.0"/>
                <geometry>
                    <sphere radius="0.03"/>
                </geometry>
                <material name="black">
                    <color rgba="0.0 0.0 0.0 1.0"/>
                </material>
            </visual>
            <collision>
                <origin xyz="0.0 0.0 0.0" rpy="0.0 0.0 0.0"/>
                <geometry>
                    <sphere radius="0.03"/>
                </geometry>
            </collision>
        </link>

        <gazebo reference="caster_wheelB">
            <material>Gazebo/White</material>
            <mu1 value="0.001"/>
            <mu2 value="0.001"/>
        </gazebo>



        <!--                Laser joint & link              -->
        <joint name="lidar_joint" type="fixed">
            <parent link="chassis_link"/>
            <child link="laser_frame"/>
            <origin xyz="0 0 0.125" rpy="0.0 0 0"/>
        </joint>
        
        <link name="laser_frame">
            <inertial>
                <origin xyz="0.0 0.0 0.0" rpy="0.0 0.0 0.0"/>
                <mass value="0.200"/>
                <inertia ixx="0.00036" ixy="0.0" ixz="0.0" iyy="0.0" iyz="0.0" izz="0.0003433"/>
            </inertial>
            <visual>
                <origin xyz="0.0 0.0 0.0" rpy=" 0.0 0.0 0.0"/>
                <geometry>
                    <cylinder radius="0.06" length="0.05"/> 
                </geometry>
                <material name="orange">
                    <color rgba="1.0 0.3 0.0 1.0"/>
                </material>
            </visual>
            <collision>
                <origin xyz="0.0 0.0 0.0" rpy="0.0 0.0 0.0"/>
                <geometry>
                    <cylinder radius="0.06" length="0.05"/> 
                </geometry>
            </collision>
        </link>

</robot>